submitit ERROR (2022-12-08 01:47:21,122) - Submitted job triggered an exception
Traceback (most recent call last):
  File "C:\Program Files\WindowsApps\PythonSoftwareFoundation.Python.3.9_3.9.3568.0_x64__qbz5n2kfra8p0\lib\runpy.py", line 197, in _run_module_as_main
    return _run_code(code, main_globals, None,
  File "C:\Program Files\WindowsApps\PythonSoftwareFoundation.Python.3.9_3.9.3568.0_x64__qbz5n2kfra8p0\lib\runpy.py", line 87, in _run_code
    exec(code, run_globals)
  File "C:\Users\pc\AppData\Local\Packages\PythonSoftwareFoundation.Python.3.9_qbz5n2kfra8p0\LocalCache\local-packages\Python39\site-packages\submitit\core\_submit.py", line 11, in <module>
    submitit_main()
  File "C:\Users\pc\AppData\Local\Packages\PythonSoftwareFoundation.Python.3.9_qbz5n2kfra8p0\LocalCache\local-packages\Python39\site-packages\submitit\core\submission.py", line 72, in submitit_main
    process_job(args.folder)
  File "C:\Users\pc\AppData\Local\Packages\PythonSoftwareFoundation.Python.3.9_qbz5n2kfra8p0\LocalCache\local-packages\Python39\site-packages\submitit\core\submission.py", line 65, in process_job
    raise error
  File "C:\Users\pc\AppData\Local\Packages\PythonSoftwareFoundation.Python.3.9_qbz5n2kfra8p0\LocalCache\local-packages\Python39\site-packages\submitit\core\submission.py", line 53, in process_job
    env._handle_signals(paths, delayed)
  File "C:\Users\pc\AppData\Local\Packages\PythonSoftwareFoundation.Python.3.9_qbz5n2kfra8p0\LocalCache\local-packages\Python39\site-packages\submitit\core\job_environment.py", line 153, in _handle_signals
    signal.signal(self._usr_sig(), handler.checkpoint_and_try_requeue)
  File "C:\Users\pc\AppData\Local\Packages\PythonSoftwareFoundation.Python.3.9_qbz5n2kfra8p0\LocalCache\local-packages\Python39\site-packages\submitit\core\job_environment.py", line 141, in _usr_sig
    raise RuntimeError(
RuntimeError: Unknown signal SIGUSR2, you may need to unset or update env var SUBMITIT_PREEMPT_SIGNAL (Eg: USR2)
